<mujoco model="hexapod">
    <compiler angle="radian" inertiafromgeom="true" meshdir="meshes/"/>
    <size njmax="500" nconmax="100"/>

    <default>
        <joint armature="0.5" damping="1" limited="true"/>
        <geom condim="3" friction="1.5 0.5 0.5"/>
        <position ctrllimited="false" forcelimited="false" gear="1" kp="100"/>
    </default>


    <asset>
        <mesh name="body_mesh" file="body_mesh.stl"/>
        <mesh name="coxa_mesh" file="coxa_mesh.stl"/>
        <mesh name="femur_mesh" file="femur_mesh.stl"/>
        <mesh name="tibia_mesh" file="tibia_mesh.stl"/>
        <texture builtin="checker" height="512" name="texplane" rgb1=".2 .3 .4" rgb2=".1 0.15 0.2" type="2d"
                 width="512"/>
        <texture type="skybox" builtin="gradient" rgb1=".2 .3 .4" rgb2=".1 0.15 0.2" width="32" height="32"/>

        <material name="floorplane" reflectance="0.5" texrepeat="1 1" texture="texplane" texuniform="true"/>

    </asset>


    <worldbody>
        <geom name="floor" pos="0. 0. -0.14493" size="3 3 .125" type="plane" condim="3" material="floorplane"/>

        <light directional="true" ambient="0.2 0.2 0.2" diffuse="0.8 0.8 0.8" specular="0.3 0.3 0.3" castshadow="false"
               pos="0 0 4" dir="0 0 -1" name="light0"/>


        <body name="torso">
            <camera name="track" mode="trackcom" pos="0 -3 0.3" xyaxes="1 0 0 0 0 1"/>

            <geom pos="0 0.251 0.137" quat="0.707105 0 0 0.707108" type="mesh" group="1"
                  rgba="1 1 1 1" mesh="body_mesh" mass="0.4"/>
            <joint armature="0" damping="0" limited="false" name="torso" pos="0 0 0" type="free"/>

            <!--LEG LEFT MID-->
            <body name="coxa_LM" pos="0.00053 0.13806 0.16287">
                <inertial pos="0 0 0" quat="0.5 0.5 -0.5 0.5" mass="0.1" diaginertia="6.125e-05 5.1458e-05 5.1458e-05"/>
                <joint name="coxa_LM" pos="0 0 0" axis="0 0 1" limited="true" range="-0.78 0.78"/>
                <geom pos="0.00047 -0.02306 -0.02187" quat="0.707105 0 0 0.707108" type="mesh"
                      group="1" rgba="0 0 0 1" mesh="coxa_mesh"/>
                <body name="femur_LM" pos="-0.01486 -0.04843 -0.02454">
                    <inertial pos="0 0 0" quat="0.5 0.5 -0.5 0.5" mass="0.1"
                              diaginertia="6.125e-05 5.1458e-05 5.1458e-05"/>
                    <joint name="femur_LM" pos="0 0 0" axis="1 0 0" limited="true" range="-0.7848 0.78"
                    />
                    <geom pos="0.0343 -0.03663 -0.0133" type="mesh" group="1" rgba="0 0 0 1"
                          mesh="femur_mesh"/>
                    <body name="tibia_LM" pos="0.03215 -0.06142 -0.01381">
                        <inertial pos="0 0 0" quat="0.5 0.5 -0.5 0.5" mass="0.1"
                                  diaginertia="6.125e-05 5.1458e-05 5.1458e-05"/>
                        <joint name="tibia_LM" pos="0 0 0" axis="1 0 0" limited="true" range="-0.78 0.78"
                        />
                        <geom pos="-0.01782 -0.02821 -0.06052" type="mesh" group="1"
                              rgba="0 0 0 1" mesh="tibia_mesh" name="tibia_LM"/>
                    </body>
                </body>
            </body>

            <!--LEG LEFT FRONT-->
            <body name="coxa_LF" pos="-0.12284 0.18389 0.16287" quat="0.923956 0 0 -0.382499">
                <inertial pos="0 0 0" quat="0.5 0.5 -0.5 0.5" mass="0.1" diaginertia="6.125e-05 5.1458e-05 5.1458e-05"/>
                <joint name="coxa_LF" pos="0 0 0" axis="0 0 1" limited="true" range="-0.78 0.78"/>
                <geom pos="0.00047 -0.02306 -0.02187" quat="0.707105 0 0 0.707108" type="mesh"

                      group="1" rgba="0 0 0 1" mesh="coxa_mesh"/>
                <body name="femur_LF" pos="-0.01486 -0.04843 -0.02454">
                    <inertial pos="0 0 0" quat="0.5 0.5 -0.5 0.5" mass="0.1"
                              diaginertia="6.125e-05 5.1458e-05 5.1458e-05"/>
                    <joint name="femur_LF" pos="0 0 0" axis="1 0 0" limited="true" range="-0.7848 0.78"
                    />
                    <geom pos="0.0343 -0.03663 -0.0133" type="mesh" group="1" rgba="0 0 0 1"
                          mesh="femur_mesh"/>
                    <body name="tibia_LF" pos="0.03215 -0.06142 -0.01381">
                        <inertial pos="0 0 0" quat="0.5 0.5 -0.5 0.5" mass="0.1"
                                  diaginertia="6.125e-05 5.1458e-05 5.1458e-05"/>
                        <joint name="tibia_LF" pos="0 0 0" axis="1 0 0" limited="true" range="-0.78 0.78"
                        />
                        <geom pos="-0.01782 -0.02821 -0.06052" type="mesh" group="1"
                              rgba="0 0 0 1" mesh="tibia_mesh" name="tibia_LF"/>
                    </body>
                </body>
            </body>


            <!--LEG RIGHT FRONT-->
            <body name="coxa_RF" pos="-0.12284 0.30204 0.16287" quat="0.382773 0 0 -0.923842">
                <inertial pos="0 0 0" quat="0.5 0.5 -0.5 0.5" mass="0.1" diaginertia="6.125e-05 5.1458e-05 5.1458e-05"/>
                <joint name="coxa_RF" pos="0 0 0" axis="0 0 1" limited="true" range="-0.78 0.78"/>
                <geom pos="0.00047 -0.02306 -0.02187" quat="0.707105 0 0 0.707108" type="mesh"

                      group="1" rgba="0 0 0 1" mesh="coxa_mesh"/>
                <body name="femur_RF" pos="-0.01486 -0.04843 -0.02454">
                    <inertial pos="0 0 0" quat="0.5 0.5 -0.5 0.5" mass="0.1"
                              diaginertia="6.125e-05 5.1458e-05 5.1458e-05"/>
                    <joint name="femur_RF" pos="0 0 0" axis="1 0 0" limited="true" range="-0.7848 0.78"
                    />
                    <geom pos="0.0343 -0.03663 -0.0133" type="mesh" group="1" rgba="0 0 0 1"
                          mesh="femur_mesh"/>
                    <body name="tibia_RF" pos="0.03215 -0.06142 -0.01381">
                        <inertial pos="0 0 0" quat="0.5 0.5 -0.5 0.5" mass="0.1"
                                  diaginertia="6.125e-05 5.1458e-05 5.1458e-05"/>
                        <joint name="tibia_RF" pos="0 0 0" axis="1 0 0" limited="true" range="-0.78 0.78"
                        />
                        <geom pos="-0.01782 -0.02821 -0.06052" type="mesh" group="1"
                              rgba="0 0 0 1" mesh="tibia_mesh" name="tibia_RF"/>
                    </body>
                </body>
            </body>


            <!--LEG RIGHT MID-->
            <body name="coxa_RM" pos="0.00053 0.34564 0.16287" quat="0.000796327 0 0 1">
                <inertial pos="0 0 0" quat="0.5 0.5 -0.5 0.5" mass="0.1" diaginertia="6.125e-05 5.1458e-05 5.1458e-05"/>
                <joint name="coxa_RM" pos="0 0 0" axis="0 0 1" limited="true" range="-0.78 0.78"/>
                <geom pos="0.00047 -0.02306 -0.02187" quat="0.707105 0 0 0.707108" type="mesh"

                      group="1" rgba="0 0 0 1" mesh="coxa_mesh"/>
                <body name="femur_RM" pos="-0.01486 -0.04843 -0.02454">
                    <inertial pos="0 0 0" quat="0.5 0.5 -0.5 0.5" mass="0.1"
                              diaginertia="6.125e-05 5.1458e-05 5.1458e-05"/>
                    <joint name="femur_RM" pos="0 0 0" axis="1 0 0" limited="true" range="-0.7848 0.78"
                    />
                    <geom pos="0.0343 -0.03663 -0.0133" type="mesh" group="1" rgba="0 0 0 1"
                          mesh="femur_mesh"/>
                    <body name="tibia_RM" pos="0.03215 -0.06142 -0.01381">
                        <inertial pos="0 0 0" quat="0.5 0.5 -0.5 0.5" mass="0.1"
                                  diaginertia="6.125e-05 5.1458e-05 5.1458e-05"/>
                        <joint name="tibia_RM" pos="0 0 0" axis="1 0 0" limited="true" range="-0.78 0.78"
                        />
                        <geom pos="-0.01782 -0.02821 -0.06052" type="mesh" group="1"
                              rgba="0 0 0 1" mesh="tibia_mesh" name="tibia_RM"/>
                    </body>
                </body>
            </body>


            <!--LEG RIGHT REAR-->
            <body name="coxa_RR" pos="0.12284 0.30205 0.16287" quat="0.385543 0 0 0.92269">
                <inertial pos="0 0 0" quat="0.5 0.5 -0.5 0.5" mass="0.1" diaginertia="6.125e-05 5.1458e-05 5.1458e-05"/>
                <joint name="coxa_RR" pos="0 0 0" axis="0 0 1" limited="true" range="-0.78 0.78"/>
                <geom pos="0.00047 -0.02306 -0.02187" quat="0.707105 0 0 0.707108" type="mesh"

                      group="1" rgba="0 0 0 1" mesh="coxa_mesh"/>
                <body name="femur_RR" pos="-0.01486 -0.04843 -0.02454">
                    <inertial pos="0 0 0" quat="0.5 0.5 -0.5 0.5" mass="0.1"
                              diaginertia="6.125e-05 5.1458e-05 5.1458e-05"/>
                    <joint name="femur_RR" pos="0 0 0" axis="1 0 0" limited="true" range="-0.7848 0.78"
                    />
                    <geom pos="0.0343 -0.03663 -0.0133" type="mesh" group="1" rgba="0 0 0 1"
                          mesh="femur_mesh"/>
                    <body name="tibia_RR" pos="0.03215 -0.06142 -0.01381">
                        <inertial pos="0 0 0" quat="0.5 0.5 -0.5 0.5" mass="0.1"
                                  diaginertia="6.125e-05 5.1458e-05 5.1458e-05"/>
                        <joint name="tibia_RR" pos="0 0 0" axis="1 0 0" limited="true" range="-0.78 0.78"
                        />
                        <geom pos="-0.01782 -0.02821 -0.06052" type="mesh" group="1"
                              rgba="0 0 0 1" mesh="tibia_mesh" name="tibia_RR"/>
                    </body>
                </body>
            </body>

            <!--LEG LEFT REAR-->
            <body name="coxa_LR" pos="0.12284 0.18389 0.16287" quat="0.923956 0 0 0.382499">
                <inertial pos="0 0 0" quat="0.5 0.5 -0.5 0.5" mass="0.1" diaginertia="6.125e-05 5.1458e-05 5.1458e-05"/>
                <joint name="coxa_LR" pos="0 0 0" axis="0 0 1" limited="true" range="-0.78 0.78"/>
                <geom pos="0.00047 -0.02306 -0.02187" quat="0.707105 0 0 0.707108" type="mesh"

                      group="1" rgba="0 0 0 1" mesh="coxa_mesh"/>
                <body name="femur_LR" pos="-0.01486 -0.04843 -0.02454">
                    <inertial pos="0 0 0" quat="0.5 0.5 -0.5 0.5" mass="0.1"
                              diaginertia="6.125e-05 5.1458e-05 5.1458e-05"/>
                    <joint name="femur_LR" pos="0 0 0" axis="1 0 0" limited="true" range="-0.7848 0.78"
                    />
                    <geom pos="0.0343 -0.03663 -0.0133" type="mesh" group="1" rgba="0 0 0 1"
                          mesh="femur_mesh"/>
                    <body name="tibia_LR" pos="0.03215 -0.06142 -0.01381">
                        <inertial pos="0 0 0" quat="0.5 0.5 -0.5 0.5" mass="0.1"
                                  diaginertia="6.125e-05 5.1458e-05 5.1458e-05"/>
                        <joint name="tibia_LR" pos="0 0 0" axis="1 0 0" limited="true" range="-0.78 0.78"
                        />
                        <geom pos="-0.01782 -0.02821 -0.06052" type="mesh" group="1"
                              rgba="0 0 0 1" mesh="tibia_mesh" name="tibia_LR"/>
                    </body>
                </body>
            </body>
        </body>
    </worldbody>


    <actuator>
        <position name="coxa_LM" joint="coxa_LM"/>
        <position name="femur_LM" joint="femur_LM"/>
        <position name="tibia_LM" joint="tibia_LM"/>
        <position name="coxa_LF" joint="coxa_LF"/>
        <position name="femur_LF" joint="femur_LF"/>
        <position name="tibia_LF" joint="tibia_LF"/>
        <position name="coxa_RF" joint="coxa_RF"/>
        <position name="femur_RF" joint="femur_RF"/>
        <position name="tibia_RF" joint="tibia_RF"/>
        <position name="coxa_RM" joint="coxa_RM"/>
        <position name="femur_RM" joint="femur_RM"/>
        <position name="tibia_RM" joint="tibia_RM"/>
        <position name="coxa_RR" joint="coxa_RR"/>
        <position name="femur_RR" joint="femur_RR"/>
        <position name="tibia_RR" joint="tibia_RR"/>
        <position name="coxa_LR" joint="coxa_LR"/>
        <position name="femur_LR" joint="femur_LR"/>
        <position name="tibia_LR" joint="tibia_LR"/>
    </actuator>

</mujoco>
